services.logging_service 2022-10-20 07:13:43,978 ERROR There is an event data parsing error! Unterminated string starting at: line 1 column 863 (char 862)
Traceback (most recent call last):
  File "/Users/tunahanoguz/PycharmProjects/kafka-wikimedia-events/services/producer_service.py", line 43, in _parse_event_data
    return WikimediaEvent(id=event_meta['id'],
  File "/usr/local/Cellar/python@3.9/3.9.1/Frameworks/Python.framework/Versions/3.9/lib/python3.9/json/__init__.py", line 346, in loads
    return _default_decoder.decode(s)
  File "/usr/local/Cellar/python@3.9/3.9.1/Frameworks/Python.framework/Versions/3.9/lib/python3.9/json/decoder.py", line 337, in decode
    obj, end = self.raw_decode(s, idx=_w(s, 0).end())
  File "/usr/local/Cellar/python@3.9/3.9.1/Frameworks/Python.framework/Versions/3.9/lib/python3.9/json/decoder.py", line 353, in raw_decode
    obj, end = self.scan_once(s, idx)
json.decoder.JSONDecodeError: Unterminated string starting at: line 1 column 863 (char 862)

During handling of the above exception, another exception occurred:

Traceback (most recent call last):
  File "/Users/tunahanoguz/PycharmProjects/kafka-wikimedia-events/services/producer_service.py", line 33, in send_wikimedia_events
    wikimedia_event = self._parse_event_data(event.data)
  File "/Users/tunahanoguz/PycharmProjects/kafka-wikimedia-events/services/producer_service.py", line 51, in _parse_event_data
exceptions.event_data_parsing_exception.EventDataParsingException: There is an event data parsing error! Unterminated string starting at: line 1 column 863 (char 862)
services.logging_service 2022-10-20 07:13:44,341 ERROR There is an event data parsing error! Unterminated string starting at: line 1 column 649 (char 648)
Traceback (most recent call last):
  File "/Users/tunahanoguz/PycharmProjects/kafka-wikimedia-events/services/producer_service.py", line 43, in _parse_event_data
    return WikimediaEvent(id=event_meta['id'],
  File "/usr/local/Cellar/python@3.9/3.9.1/Frameworks/Python.framework/Versions/3.9/lib/python3.9/json/__init__.py", line 346, in loads
    return _default_decoder.decode(s)
  File "/usr/local/Cellar/python@3.9/3.9.1/Frameworks/Python.framework/Versions/3.9/lib/python3.9/json/decoder.py", line 337, in decode
    obj, end = self.raw_decode(s, idx=_w(s, 0).end())
  File "/usr/local/Cellar/python@3.9/3.9.1/Frameworks/Python.framework/Versions/3.9/lib/python3.9/json/decoder.py", line 353, in raw_decode
    obj, end = self.scan_once(s, idx)
json.decoder.JSONDecodeError: Unterminated string starting at: line 1 column 649 (char 648)

During handling of the above exception, another exception occurred:

Traceback (most recent call last):
  File "/Users/tunahanoguz/PycharmProjects/kafka-wikimedia-events/services/producer_service.py", line 33, in send_wikimedia_events
    wikimedia_event = self._parse_event_data(event.data)
  File "/Users/tunahanoguz/PycharmProjects/kafka-wikimedia-events/services/producer_service.py", line 51, in _parse_event_data
exceptions.event_data_parsing_exception.EventDataParsingException: There is an event data parsing error! Unterminated string starting at: line 1 column 649 (char 648)
services.logging_service 2022-10-20 07:13:45,079 ERROR There is an event data parsing error! Unterminated string starting at: line 1 column 44 (char 43)
Traceback (most recent call last):
  File "/Users/tunahanoguz/PycharmProjects/kafka-wikimedia-events/services/producer_service.py", line 43, in _parse_event_data
    return WikimediaEvent(id=event_meta['id'],
  File "/usr/local/Cellar/python@3.9/3.9.1/Frameworks/Python.framework/Versions/3.9/lib/python3.9/json/__init__.py", line 346, in loads
    return _default_decoder.decode(s)
  File "/usr/local/Cellar/python@3.9/3.9.1/Frameworks/Python.framework/Versions/3.9/lib/python3.9/json/decoder.py", line 337, in decode
    obj, end = self.raw_decode(s, idx=_w(s, 0).end())
  File "/usr/local/Cellar/python@3.9/3.9.1/Frameworks/Python.framework/Versions/3.9/lib/python3.9/json/decoder.py", line 353, in raw_decode
    obj, end = self.scan_once(s, idx)
json.decoder.JSONDecodeError: Unterminated string starting at: line 1 column 44 (char 43)

During handling of the above exception, another exception occurred:

Traceback (most recent call last):
  File "/Users/tunahanoguz/PycharmProjects/kafka-wikimedia-events/services/producer_service.py", line 33, in send_wikimedia_events
    wikimedia_event = self._parse_event_data(event.data)
  File "/Users/tunahanoguz/PycharmProjects/kafka-wikimedia-events/services/producer_service.py", line 51, in _parse_event_data
exceptions.event_data_parsing_exception.EventDataParsingException: There is an event data parsing error! Unterminated string starting at: line 1 column 44 (char 43)
services.logging_service 2022-10-20 07:13:45,274 ERROR There is an event data parsing error! Unterminated string starting at: line 1 column 100 (char 99)
Traceback (most recent call last):
  File "/Users/tunahanoguz/PycharmProjects/kafka-wikimedia-events/services/producer_service.py", line 43, in _parse_event_data
    return WikimediaEvent(id=event_meta['id'],
  File "/usr/local/Cellar/python@3.9/3.9.1/Frameworks/Python.framework/Versions/3.9/lib/python3.9/json/__init__.py", line 346, in loads
    return _default_decoder.decode(s)
  File "/usr/local/Cellar/python@3.9/3.9.1/Frameworks/Python.framework/Versions/3.9/lib/python3.9/json/decoder.py", line 337, in decode
    obj, end = self.raw_decode(s, idx=_w(s, 0).end())
  File "/usr/local/Cellar/python@3.9/3.9.1/Frameworks/Python.framework/Versions/3.9/lib/python3.9/json/decoder.py", line 353, in raw_decode
    obj, end = self.scan_once(s, idx)
json.decoder.JSONDecodeError: Unterminated string starting at: line 1 column 100 (char 99)

During handling of the above exception, another exception occurred:

Traceback (most recent call last):
  File "/Users/tunahanoguz/PycharmProjects/kafka-wikimedia-events/services/producer_service.py", line 33, in send_wikimedia_events
    wikimedia_event = self._parse_event_data(event.data)
  File "/Users/tunahanoguz/PycharmProjects/kafka-wikimedia-events/services/producer_service.py", line 51, in _parse_event_data
exceptions.event_data_parsing_exception.EventDataParsingException: There is an event data parsing error! Unterminated string starting at: line 1 column 100 (char 99)
services.logging_service 2022-10-20 07:13:45,608 ERROR There is an event data parsing error! Unterminated string starting at: line 1 column 863 (char 862)
Traceback (most recent call last):
  File "/Users/tunahanoguz/PycharmProjects/kafka-wikimedia-events/services/producer_service.py", line 43, in _parse_event_data
    return WikimediaEvent(id=event_meta['id'],
  File "/usr/local/Cellar/python@3.9/3.9.1/Frameworks/Python.framework/Versions/3.9/lib/python3.9/json/__init__.py", line 346, in loads
    return _default_decoder.decode(s)
  File "/usr/local/Cellar/python@3.9/3.9.1/Frameworks/Python.framework/Versions/3.9/lib/python3.9/json/decoder.py", line 337, in decode
    obj, end = self.raw_decode(s, idx=_w(s, 0).end())
  File "/usr/local/Cellar/python@3.9/3.9.1/Frameworks/Python.framework/Versions/3.9/lib/python3.9/json/decoder.py", line 353, in raw_decode
    obj, end = self.scan_once(s, idx)
json.decoder.JSONDecodeError: Unterminated string starting at: line 1 column 863 (char 862)

During handling of the above exception, another exception occurred:

Traceback (most recent call last):
  File "/Users/tunahanoguz/PycharmProjects/kafka-wikimedia-events/services/producer_service.py", line 33, in send_wikimedia_events
    wikimedia_event = self._parse_event_data(event.data)
  File "/Users/tunahanoguz/PycharmProjects/kafka-wikimedia-events/services/producer_service.py", line 51, in _parse_event_data
exceptions.event_data_parsing_exception.EventDataParsingException: There is an event data parsing error! Unterminated string starting at: line 1 column 863 (char 862)
services.logging_service 2022-10-20 07:13:45,609 ERROR There is an event data parsing error! Unterminated string starting at: line 1 column 155 (char 154)
Traceback (most recent call last):
  File "/Users/tunahanoguz/PycharmProjects/kafka-wikimedia-events/services/producer_service.py", line 43, in _parse_event_data
    return WikimediaEvent(id=event_meta['id'],
  File "/usr/local/Cellar/python@3.9/3.9.1/Frameworks/Python.framework/Versions/3.9/lib/python3.9/json/__init__.py", line 346, in loads
    return _default_decoder.decode(s)
  File "/usr/local/Cellar/python@3.9/3.9.1/Frameworks/Python.framework/Versions/3.9/lib/python3.9/json/decoder.py", line 337, in decode
    obj, end = self.raw_decode(s, idx=_w(s, 0).end())
  File "/usr/local/Cellar/python@3.9/3.9.1/Frameworks/Python.framework/Versions/3.9/lib/python3.9/json/decoder.py", line 353, in raw_decode
    obj, end = self.scan_once(s, idx)
json.decoder.JSONDecodeError: Unterminated string starting at: line 1 column 155 (char 154)

During handling of the above exception, another exception occurred:

Traceback (most recent call last):
  File "/Users/tunahanoguz/PycharmProjects/kafka-wikimedia-events/services/producer_service.py", line 33, in send_wikimedia_events
    wikimedia_event = self._parse_event_data(event.data)
  File "/Users/tunahanoguz/PycharmProjects/kafka-wikimedia-events/services/producer_service.py", line 51, in _parse_event_data
exceptions.event_data_parsing_exception.EventDataParsingException: There is an event data parsing error! Unterminated string starting at: line 1 column 155 (char 154)
