services.logging_service 2022-10-20 07:13:47,934 ERROR There is an event data parsing error! Expecting ':' delimiter: line 1 column 632 (char 631)
Traceback (most recent call last):
  File "/Users/tunahanoguz/PycharmProjects/kafka-wikimedia-events/services/producer_service.py", line 43, in _parse_event_data
    return WikimediaEvent(id=event_meta['id'],
  File "/usr/local/Cellar/python@3.9/3.9.1/Frameworks/Python.framework/Versions/3.9/lib/python3.9/json/__init__.py", line 346, in loads
    return _default_decoder.decode(s)
  File "/usr/local/Cellar/python@3.9/3.9.1/Frameworks/Python.framework/Versions/3.9/lib/python3.9/json/decoder.py", line 337, in decode
    obj, end = self.raw_decode(s, idx=_w(s, 0).end())
  File "/usr/local/Cellar/python@3.9/3.9.1/Frameworks/Python.framework/Versions/3.9/lib/python3.9/json/decoder.py", line 353, in raw_decode
    obj, end = self.scan_once(s, idx)
json.decoder.JSONDecodeError: Expecting ':' delimiter: line 1 column 632 (char 631)

During handling of the above exception, another exception occurred:

Traceback (most recent call last):
  File "/Users/tunahanoguz/PycharmProjects/kafka-wikimedia-events/services/producer_service.py", line 33, in send_wikimedia_events
    wikimedia_event = self._parse_event_data(event.data)
  File "/Users/tunahanoguz/PycharmProjects/kafka-wikimedia-events/services/producer_service.py", line 51, in _parse_event_data
exceptions.event_data_parsing_exception.EventDataParsingException: There is an event data parsing error! Expecting ':' delimiter: line 1 column 632 (char 631)
services.logging_service 2022-10-20 07:13:47,969 ERROR There is an event data parsing error! Unterminated string starting at: line 1 column 114 (char 113)
Traceback (most recent call last):
  File "/Users/tunahanoguz/PycharmProjects/kafka-wikimedia-events/services/producer_service.py", line 43, in _parse_event_data
    return WikimediaEvent(id=event_meta['id'],
  File "/usr/local/Cellar/python@3.9/3.9.1/Frameworks/Python.framework/Versions/3.9/lib/python3.9/json/__init__.py", line 346, in loads
    return _default_decoder.decode(s)
  File "/usr/local/Cellar/python@3.9/3.9.1/Frameworks/Python.framework/Versions/3.9/lib/python3.9/json/decoder.py", line 337, in decode
    obj, end = self.raw_decode(s, idx=_w(s, 0).end())
  File "/usr/local/Cellar/python@3.9/3.9.1/Frameworks/Python.framework/Versions/3.9/lib/python3.9/json/decoder.py", line 353, in raw_decode
    obj, end = self.scan_once(s, idx)
json.decoder.JSONDecodeError: Unterminated string starting at: line 1 column 114 (char 113)

During handling of the above exception, another exception occurred:

Traceback (most recent call last):
  File "/Users/tunahanoguz/PycharmProjects/kafka-wikimedia-events/services/producer_service.py", line 33, in send_wikimedia_events
    wikimedia_event = self._parse_event_data(event.data)
  File "/Users/tunahanoguz/PycharmProjects/kafka-wikimedia-events/services/producer_service.py", line 51, in _parse_event_data
exceptions.event_data_parsing_exception.EventDataParsingException: There is an event data parsing error! Unterminated string starting at: line 1 column 114 (char 113)
services.logging_service 2022-10-20 07:13:48,198 ERROR There is an event data parsing error! Unterminated string starting at: line 1 column 556 (char 555)
Traceback (most recent call last):
  File "/Users/tunahanoguz/PycharmProjects/kafka-wikimedia-events/services/producer_service.py", line 43, in _parse_event_data
    return WikimediaEvent(id=event_meta['id'],
  File "/usr/local/Cellar/python@3.9/3.9.1/Frameworks/Python.framework/Versions/3.9/lib/python3.9/json/__init__.py", line 346, in loads
    return _default_decoder.decode(s)
  File "/usr/local/Cellar/python@3.9/3.9.1/Frameworks/Python.framework/Versions/3.9/lib/python3.9/json/decoder.py", line 337, in decode
    obj, end = self.raw_decode(s, idx=_w(s, 0).end())
  File "/usr/local/Cellar/python@3.9/3.9.1/Frameworks/Python.framework/Versions/3.9/lib/python3.9/json/decoder.py", line 353, in raw_decode
    obj, end = self.scan_once(s, idx)
json.decoder.JSONDecodeError: Unterminated string starting at: line 1 column 556 (char 555)

During handling of the above exception, another exception occurred:

Traceback (most recent call last):
  File "/Users/tunahanoguz/PycharmProjects/kafka-wikimedia-events/services/producer_service.py", line 33, in send_wikimedia_events
    wikimedia_event = self._parse_event_data(event.data)
  File "/Users/tunahanoguz/PycharmProjects/kafka-wikimedia-events/services/producer_service.py", line 51, in _parse_event_data
exceptions.event_data_parsing_exception.EventDataParsingException: There is an event data parsing error! Unterminated string starting at: line 1 column 556 (char 555)
services.logging_service 2022-10-20 07:13:48,369 ERROR There is an event data parsing error! Unterminated string starting at: line 1 column 432 (char 431)
Traceback (most recent call last):
  File "/Users/tunahanoguz/PycharmProjects/kafka-wikimedia-events/services/producer_service.py", line 43, in _parse_event_data
    return WikimediaEvent(id=event_meta['id'],
  File "/usr/local/Cellar/python@3.9/3.9.1/Frameworks/Python.framework/Versions/3.9/lib/python3.9/json/__init__.py", line 346, in loads
    return _default_decoder.decode(s)
  File "/usr/local/Cellar/python@3.9/3.9.1/Frameworks/Python.framework/Versions/3.9/lib/python3.9/json/decoder.py", line 337, in decode
    obj, end = self.raw_decode(s, idx=_w(s, 0).end())
  File "/usr/local/Cellar/python@3.9/3.9.1/Frameworks/Python.framework/Versions/3.9/lib/python3.9/json/decoder.py", line 353, in raw_decode
    obj, end = self.scan_once(s, idx)
json.decoder.JSONDecodeError: Unterminated string starting at: line 1 column 432 (char 431)

During handling of the above exception, another exception occurred:

Traceback (most recent call last):
  File "/Users/tunahanoguz/PycharmProjects/kafka-wikimedia-events/services/producer_service.py", line 33, in send_wikimedia_events
    wikimedia_event = self._parse_event_data(event.data)
  File "/Users/tunahanoguz/PycharmProjects/kafka-wikimedia-events/services/producer_service.py", line 51, in _parse_event_data
exceptions.event_data_parsing_exception.EventDataParsingException: There is an event data parsing error! Unterminated string starting at: line 1 column 432 (char 431)
services.logging_service 2022-10-20 07:13:49,016 ERROR There is an event data parsing error! Unterminated string starting at: line 1 column 434 (char 433)
Traceback (most recent call last):
  File "/Users/tunahanoguz/PycharmProjects/kafka-wikimedia-events/services/producer_service.py", line 43, in _parse_event_data
    return WikimediaEvent(id=event_meta['id'],
  File "/usr/local/Cellar/python@3.9/3.9.1/Frameworks/Python.framework/Versions/3.9/lib/python3.9/json/__init__.py", line 346, in loads
    return _default_decoder.decode(s)
  File "/usr/local/Cellar/python@3.9/3.9.1/Frameworks/Python.framework/Versions/3.9/lib/python3.9/json/decoder.py", line 337, in decode
    obj, end = self.raw_decode(s, idx=_w(s, 0).end())
  File "/usr/local/Cellar/python@3.9/3.9.1/Frameworks/Python.framework/Versions/3.9/lib/python3.9/json/decoder.py", line 353, in raw_decode
    obj, end = self.scan_once(s, idx)
json.decoder.JSONDecodeError: Unterminated string starting at: line 1 column 434 (char 433)

During handling of the above exception, another exception occurred:

Traceback (most recent call last):
  File "/Users/tunahanoguz/PycharmProjects/kafka-wikimedia-events/services/producer_service.py", line 33, in send_wikimedia_events
    wikimedia_event = self._parse_event_data(event.data)
  File "/Users/tunahanoguz/PycharmProjects/kafka-wikimedia-events/services/producer_service.py", line 51, in _parse_event_data
exceptions.event_data_parsing_exception.EventDataParsingException: There is an event data parsing error! Unterminated string starting at: line 1 column 434 (char 433)
services.logging_service 2022-10-20 07:13:49,334 ERROR There is an event data parsing error! Unterminated string starting at: line 1 column 184 (char 183)
Traceback (most recent call last):
  File "/Users/tunahanoguz/PycharmProjects/kafka-wikimedia-events/services/producer_service.py", line 43, in _parse_event_data
    return WikimediaEvent(id=event_meta['id'],
  File "/usr/local/Cellar/python@3.9/3.9.1/Frameworks/Python.framework/Versions/3.9/lib/python3.9/json/__init__.py", line 346, in loads
    return _default_decoder.decode(s)
  File "/usr/local/Cellar/python@3.9/3.9.1/Frameworks/Python.framework/Versions/3.9/lib/python3.9/json/decoder.py", line 337, in decode
    obj, end = self.raw_decode(s, idx=_w(s, 0).end())
  File "/usr/local/Cellar/python@3.9/3.9.1/Frameworks/Python.framework/Versions/3.9/lib/python3.9/json/decoder.py", line 353, in raw_decode
    obj, end = self.scan_once(s, idx)
json.decoder.JSONDecodeError: Unterminated string starting at: line 1 column 184 (char 183)

During handling of the above exception, another exception occurred:

Traceback (most recent call last):
  File "/Users/tunahanoguz/PycharmProjects/kafka-wikimedia-events/services/producer_service.py", line 33, in send_wikimedia_events
    wikimedia_event = self._parse_event_data(event.data)
  File "/Users/tunahanoguz/PycharmProjects/kafka-wikimedia-events/services/producer_service.py", line 51, in _parse_event_data
exceptions.event_data_parsing_exception.EventDataParsingException: There is an event data parsing error! Unterminated string starting at: line 1 column 184 (char 183)
